<?xml version="1.0" ?>
<robot name="grid_bot" xmlns:xacro="http://www.ros.org/wiki/xacro">

<xacro:include filename="$(find grid_bot_description)/urdf/materials.xacro" />
<xacro:include filename="$(find grid_bot_description)/urdf/grid_bot.trans" />
<xacro:include filename="$(find grid_bot_description)/urdf/grid_bot.gazebo" />
<link name="base_link">
  <inertial>
    <origin rpy="0 0 0" xyz="0.03058315894785165 0.0024807572051702784 0.007996607847452852"/>
    <mass value="3.211035084139386"/>
    <inertia ixx="0.007574" ixy="2.7e-05" ixz="-0.001582" iyy="0.012778" iyz="-2e-06" izz="0.010865"/>
  </inertial>
  <visual>
    <origin rpy="0 0 0" xyz="0 0 0"/>
    <geometry>
      <mesh filename="package://grid_bot_description/meshes/base_link.stl" scale="0.001 0.001 0.001"/>
    </geometry>
    <material name="silver"/>
  </visual>
  <collision>
    <origin rpy="0 0 0" xyz="0 0 0"/>
    <geometry>
      <mesh filename="package://grid_bot_description/meshes/base_link.stl" scale="0.001 0.001 0.001"/>
    </geometry>
  </collision>
</link>

<link name="servo_motor_1">
  <inertial>
    <origin rpy="0 0 0" xyz="0.010587734438734408 0.0084001186327211 0.006274355737184533"/>
    <mass value="0.05328666830943237"/>
    <inertia ixx="4e-06" ixy="-0.0" ixz="-1e-06" iyy="3e-06" iyz="-0.0" izz="5e-06"/>
  </inertial>
  <visual>
    <origin rpy="0 0 0" xyz="0.031681 -0.002315 -0.005433"/>
    <geometry>
      <mesh filename="package://grid_bot_description/meshes/servo_motor_1.stl" scale="0.001 0.001 0.001"/>
    </geometry>
    <material name="silver"/>
  </visual>
  <collision>
    <origin rpy="0 0 0" xyz="0.031681 -0.002315 -0.005433"/>
    <geometry>
      <mesh filename="package://grid_bot_description/meshes/servo_motor_1.stl" scale="0.001 0.001 0.001"/>
    </geometry>
  </collision>
</link>

<link name="servo_actuator_1">
  <inertial>
    <origin rpy="0 0 0" xyz="0.004722447291877676 4.322909012226782e-07 -0.005026760619318817"/>
    <mass value="0.03497018571649247"/>
    <inertia ixx="7e-06" ixy="0.0" ixz="2e-06" iyy="5e-06" iyz="0.0" izz="5e-06"/>
  </inertial>
  <visual>
    <origin rpy="0 0 0" xyz="0.035552 -0.002315 -0.003139"/>
    <geometry>
      <mesh filename="package://grid_bot_description/meshes/servo_actuator_1.stl" scale="0.001 0.001 0.001"/>
    </geometry>
    <material name="silver"/>
  </visual>
  <collision>
    <origin rpy="0 0 0" xyz="0.035552 -0.002315 -0.003139"/>
    <geometry>
      <mesh filename="package://grid_bot_description/meshes/servo_actuator_1.stl" scale="0.001 0.001 0.001"/>
    </geometry>
  </collision>
</link>

<link name="side_pane_2">
  <inertial>
    <origin rpy="0 0 0" xyz="-0.05195651370572106 -0.0024995677090985935 -0.06871232084610449"/>
    <mass value="0.488960348592679"/>
    <inertia ixx="0.000447" ixy="0.0" ixz="-0.000275" iyy="0.001358" iyz="-0.0" izz="0.000913"/>
  </inertial>
  <visual>
    <origin rpy="0 0 0" xyz="-0.075503 0.047685 -0.079034"/>
    <geometry>
      <mesh filename="package://grid_bot_description/meshes/side_pane_2.stl" scale="0.001 0.001 0.001"/>
    </geometry>
    <material name="silver"/>
  </visual>
  <collision>
    <origin rpy="0 0 0" xyz="-0.075503 0.047685 -0.079034"/>
    <geometry>
      <mesh filename="package://grid_bot_description/meshes/side_pane_2.stl" scale="0.001 0.001 0.001"/>
    </geometry>
  </collision>
</link>

<link name="side_pane_1">
  <inertial>
    <origin rpy="0 0 0" xyz="-0.05195651370572118 0.0025004322909012305 -0.06871232084610446"/>
    <mass value="0.488960348592679"/>
    <inertia ixx="0.000447" ixy="0.0" ixz="-0.000275" iyy="0.001358" iyz="-0.0" izz="0.000913"/>
  </inertial>
  <visual>
    <origin rpy="0 0 0" xyz="-0.075503 -0.052315 -0.079034"/>
    <geometry>
      <mesh filename="package://grid_bot_description/meshes/side_pane_1.stl" scale="0.001 0.001 0.001"/>
    </geometry>
    <material name="silver"/>
  </visual>
  <collision>
    <origin rpy="0 0 0" xyz="-0.075503 -0.052315 -0.079034"/>
    <geometry>
      <mesh filename="package://grid_bot_description/meshes/side_pane_1.stl" scale="0.001 0.001 0.001"/>
    </geometry>
  </collision>
</link>

<link name="connector_rod_1">
  <inertial>
    <origin rpy="0 0 0" xyz="3.890800441760933e-07 -0.06749956770909944 -2.161915329777775e-07"/>
    <mass value="0.007490931332944163"/>
    <inertia ixx="1.1e-05" ixy="-0.0" ixz="0.0" iyy="0.0" iyz="-0.0" izz="1.1e-05"/>
  </inertial>
  <visual>
    <origin rpy="0 0 0" xyz="-0.046539 -0.069315 0.028466"/>
    <geometry>
      <mesh filename="package://grid_bot_description/meshes/connector_rod_1.stl" scale="0.001 0.001 0.001"/>
    </geometry>
    <material name="silver"/>
  </visual>
  <collision>
    <origin rpy="0 0 0" xyz="-0.046539 -0.069315 0.028466"/>
    <geometry>
      <mesh filename="package://grid_bot_description/meshes/connector_rod_1.stl" scale="0.001 0.001 0.001"/>
    </geometry>
  </collision>
</link>

<link name="left_wheel_1">
  <inertial>
    <origin rpy="0 0 0" xyz="3.8680151746156577e-07 0.0042454206608824735 -2.2070271555110765e-07"/>
    <mass value="0.10624530732840641"/>
    <inertia ixx="2e-05" ixy="-0.0" ixz="-0.0" iyy="3.9e-05" iyz="-0.0" izz="2e-05"/>
  </inertial>
  <visual>
    <origin rpy="0 0 0" xyz="-0.046539 0.065685 0.028466"/>
    <geometry>
      <mesh filename="package://grid_bot_description/meshes/left_wheel_1.stl" scale="0.001 0.001 0.001"/>
    </geometry>
    <material name="silver"/>
  </visual>
  <collision>
    <origin rpy="0 0 0" xyz="-0.046539 0.065685 0.028466"/>
    <geometry>
      <mesh filename="package://grid_bot_description/meshes/left_wheel_1.stl" scale="0.001 0.001 0.001"/>
    </geometry>
  </collision>
</link>

<link name="right_wheel_1">
  <inertial>
    <origin rpy="0 0 0" xyz="3.8680151760034365e-07 -0.004244554213330684 -2.2070271556498544e-07"/>
    <mass value="0.10624530732840641"/>
    <inertia ixx="2e-05" ixy="-0.0" ixz="-0.0" iyy="3.9e-05" iyz="-0.0" izz="2e-05"/>
  </inertial>
  <visual>
    <origin rpy="0 0 0" xyz="-0.046539 -0.069315 0.028466"/>
    <geometry>
      <mesh filename="package://grid_bot_description/meshes/right_wheel_1.stl" scale="0.001 0.001 0.001"/>
    </geometry>
    <material name="silver"/>
  </visual>
  <collision>
    <origin rpy="0 0 0" xyz="-0.046539 -0.069315 0.028466"/>
    <geometry>
      <mesh filename="package://grid_bot_description/meshes/right_wheel_1.stl" scale="0.001 0.001 0.001"/>
    </geometry>
  </collision>
</link>

<link name="castor_wheel_1">
  <inertial>
    <origin rpy="0 0 0" xyz="-4.60694217933183e-06 1.876423122246793e-05 -0.007087258397097118"/>
    <mass value="0.036526757425163855"/>
    <inertia ixx="5e-06" ixy="-0.0" ixz="-0.0" iyy="4e-06" iyz="0.0" izz="5e-06"/>
  </inertial>
  <visual>
    <origin rpy="0 0 0" xyz="0.040997 -0.002315 0.031466"/>
    <geometry>
      <mesh filename="package://grid_bot_description/meshes/castor_wheel_1.stl" scale="0.001 0.001 0.001"/>
    </geometry>
    <material name="silver"/>
  </visual>
  <collision>
    <origin rpy="0 0 0" xyz="0.040997 -0.002315 0.031466"/>
    <geometry>
      <mesh filename="package://grid_bot_description/meshes/castor_wheel_1.stl" scale="0.001 0.001 0.001"/>
    </geometry>
  </collision>
</link>

<link name="left_wheel_tyre_1">
  <inertial>
    <origin rpy="0 0 0" xyz="3.890801221415052e-07 0.005000419728007896 -2.1619153321023044e-07"/>
    <mass value="0.003489570869816107"/>
    <inertia ixx="1e-06" ixy="0.0" ixz="-0.0" iyy="2e-06" iyz="0.0" izz="1e-06"/>
  </inertial>
  <visual>
    <origin rpy="0 0 0" xyz="-0.046539 0.06644 0.028466"/>
    <geometry>
      <mesh filename="package://grid_bot_description/meshes/left_wheel_tyre_1.stl" scale="0.001 0.001 0.001"/>
    </geometry>
    <material name="silver"/>
  </visual>
  <collision>
    <origin rpy="0 0 0" xyz="-0.046539 0.06644 0.028466"/>
    <geometry>
      <mesh filename="package://grid_bot_description/meshes/left_wheel_tyre_1.stl" scale="0.001 0.001 0.001"/>
    </geometry>
  </collision>
</link>

<link name="right_wheel_tyre_1">
  <inertial>
    <origin rpy="0 0 0" xyz="3.890801222733442e-07 0.005000444853794736 -2.1619153322410822e-07"/>
    <mass value="0.003489570869816107"/>
    <inertia ixx="1e-06" ixy="-0.0" ixz="-0.0" iyy="2e-06" iyz="0.0" izz="1e-06"/>
  </inertial>
  <visual>
    <origin rpy="0 0 0" xyz="-0.046539 -0.06007 0.028466"/>
    <geometry>
      <mesh filename="package://grid_bot_description/meshes/right_wheel_tyre_1.stl" scale="0.001 0.001 0.001"/>
    </geometry>
    <material name="silver"/>
  </visual>
  <collision>
    <origin rpy="0 0 0" xyz="-0.046539 -0.06007 0.028466"/>
    <geometry>
      <mesh filename="package://grid_bot_description/meshes/right_wheel_tyre_1.stl" scale="0.001 0.001 0.001"/>
    </geometry>
  </collision>
</link>

<link name="identifier_1">
  <inertial>
    <origin rpy="0 0 0" xyz="-0.035722546362137245 0.0068016973274355515 -0.020595866570633573"/>
    <mass value="0.0006372800256449409"/>
    <inertia ixx="0.0" ixy="0.0" ixz="-0.0" iyy="0.0" iyz="0.0" izz="0.0"/>
  </inertial>
  <visual>
    <origin rpy="0 0 0" xyz="-0.069003 0.005185 -0.082534"/>
    <geometry>
      <mesh filename="package://grid_bot_description/meshes/identifier_1.stl" scale="0.001 0.001 0.001"/>
    </geometry>
    <material name="silver"/>
  </visual>
  <collision>
    <origin rpy="0 0 0" xyz="-0.069003 0.005185 -0.082534"/>
    <geometry>
      <mesh filename="package://grid_bot_description/meshes/identifier_1.stl" scale="0.001 0.001 0.001"/>
    </geometry>
  </collision>
</link>

<joint name="servo_fix" type="fixed">
  <origin rpy="0 0 0" xyz="-0.031681 0.002315 0.005433"/>
  <parent link="base_link"/>
  <child link="servo_motor_1"/>
</joint>

<joint name="servo_joint" type="revolute">
  <origin rpy="0 0 0" xyz="-0.003871 0.0 -0.002294"/>
  <parent link="servo_motor_1"/>
  <child link="servo_actuator_1"/>
  <axis xyz="0.860292 0.0 0.509802"/>
  <limit effort="100" lower="0.0" upper="3.141593" velocity="100"/>
</joint>

<joint name="left_pane_fix" type="fixed">
  <origin rpy="0 0 0" xyz="0.075503 -0.047685 0.079034"/>
  <parent link="base_link"/>
  <child link="side_pane_2"/>
</joint>

<joint name="right_pane_fix" type="fixed">
  <origin rpy="0 0 0" xyz="0.075503 0.052315 0.079034"/>
  <parent link="base_link"/>
  <child link="side_pane_1"/>
</joint>

<joint name="connector_fix" type="fixed">
  <origin rpy="0 0 0" xyz="0.046539 0.069315 -0.028466"/>
  <parent link="base_link"/>
  <child link="connector_rod_1"/>
</joint>

<joint name="left_wheel_joint" type="continuous">
  <origin rpy="0 0 0" xyz="0.0 -0.135 0.0"/>
  <parent link="connector_rod_1"/>
  <child link="left_wheel_1"/>
  <axis xyz="-0.0 -1.0 -0.0"/>
</joint>

<joint name="right_wheel_joint" type="continuous">
  <origin rpy="0 0 0" xyz="0.0 0.0 0.0"/>
  <parent link="connector_rod_1"/>
  <child link="right_wheel_1"/>
  <axis xyz="0.0 -1.0 -0.0"/>
</joint>

<joint name="castor_joint" type="fixed">
  <origin rpy="0 0 0" xyz="-0.040997 0.002315 -0.031466"/>
  <parent link="base_link"/>
  <child link="castor_wheel_1"/>
</joint>

<joint name="left_tyre_fix" type="fixed">
  <origin rpy="0 0 0" xyz="0.0 -0.000755 0.0"/>
  <parent link="left_wheel_1"/>
  <child link="left_wheel_tyre_1"/>
</joint>

<joint name="right_tyre_fix" type="fixed">
  <origin rpy="0 0 0" xyz="0.0 -0.009245 0.0"/>
  <parent link="right_wheel_1"/>
  <child link="right_wheel_tyre_1"/>
</joint>

<joint name="identifier_fix" type="fixed">
  <origin rpy="0 0 0" xyz="0.069003 -0.005185 0.082534"/>
  <parent link="base_link"/>
  <child link="identifier_1"/>
</joint>

</robot>
