<?xml version="1.0" ?>
<robot name="grid_bot_3" xmlns:xacro="http://www.ros.org/wiki/xacro">

<xacro:include filename="$(find grid_bot_3_description)/urdf/materials.xacro" />
<xacro:include filename="$(find grid_bot_3_description)/urdf/grid_bot_3.trans" />
<xacro:include filename="$(find grid_bot_3_description)/urdf/grid_bot_3.gazebo" />
<link name="base_link">
  <visual>
    <origin rpy="0 0 0" xyz="0 0 0"/>
    <geometry>
      <mesh filename="package://grid_bot_3_description/meshes/base_link.stl" scale="0.001 0.001 0.001"/>
    </geometry>
    <material name="silver"/>
  </visual>
  <collision>
    <origin rpy="0 0 0" xyz="0 0 0"/>
    <geometry>
      <mesh filename="package://grid_bot_3_description/meshes/base_link.stl" scale="0.001 0.001 0.001"/>
    </geometry>
  </collision>
</link>

<link name="servo_motor_1">
  <inertial>
    <origin rpy="0 0 0" xyz="0.010587734438734408 0.0084001186327211 0.006274355737184533"/>
    <mass value="0.05328666830943237"/>
    <inertia ixx="4e-06" ixy="-0.0" ixz="-1e-06" iyy="3e-06" iyz="-0.0" izz="5e-06"/>
  </inertial>
  <visual>
    <origin rpy="0 0 0" xyz="0.031681 -0.002315 -0.005433"/>
    <geometry>
      <mesh filename="package://grid_bot_3_description/meshes/servo_motor_1.stl" scale="0.001 0.001 0.001"/>
    </geometry>
    <material name="silver"/>
  </visual>
  <collision>
    <origin rpy="0 0 0" xyz="0.031681 -0.002315 -0.005433"/>
    <geometry>
      <mesh filename="package://grid_bot_3_description/meshes/servo_motor_1.stl" scale="0.001 0.001 0.001"/>
    </geometry>
  </collision>
</link>

<link name="servo_actuator_1">
  <inertial>
    <origin rpy="0 0 0" xyz="0.004722447291877686 4.322909012404591e-07 -0.005026760619318825"/>
    <mass value="0.034970185716492505"/>
    <inertia ixx="7e-06" ixy="0.0" ixz="2e-06" iyy="5e-06" iyz="0.0" izz="5e-06"/>
  </inertial>
  <visual>
    <origin rpy="0 0 0" xyz="0.035552 -0.002315 -0.003139"/>
    <geometry>
      <mesh filename="package://grid_bot_3_description/meshes/servo_actuator_1.stl" scale="0.001 0.001 0.001"/>
    </geometry>
    <material name="silver"/>
  </visual>
  <collision>
    <origin rpy="0 0 0" xyz="0.035552 -0.002315 -0.003139"/>
    <geometry>
      <mesh filename="package://grid_bot_3_description/meshes/servo_actuator_1.stl" scale="0.001 0.001 0.001"/>
    </geometry>
  </collision>
</link>

<link name="side_pane_2">
  <inertial>
    <origin rpy="0 0 0" xyz="-0.05840087932305019 -0.0024995677090986004 -0.07001406727133204"/>
    <mass value="0.441860348592679"/>
    <inertia ixx="0.000382" ixy="0.0" ixz="-0.000236" iyy="0.001103" iyz="-0.0" izz="0.000722"/>
  </inertial>
  <visual>
    <origin rpy="0 0 0" xyz="-0.075503 0.047685 -0.079034"/>
    <geometry>
      <mesh filename="package://grid_bot_3_description/meshes/side_pane_2.stl" scale="0.001 0.001 0.001"/>
    </geometry>
    <material name="silver"/>
  </visual>
  <collision>
    <origin rpy="0 0 0" xyz="-0.075503 0.047685 -0.079034"/>
    <geometry>
      <mesh filename="package://grid_bot_3_description/meshes/side_pane_2.stl" scale="0.001 0.001 0.001"/>
    </geometry>
  </collision>
</link>

<link name="side_pane_1">
  <inertial>
    <origin rpy="0 0 0" xyz="-0.05840087932305031 0.0025004322909012236 -0.07001406727133201"/>
    <mass value="0.441860348592679"/>
    <inertia ixx="0.000382" ixy="0.0" ixz="-0.000236" iyy="0.001103" iyz="-0.0" izz="0.000722"/>
  </inertial>
  <visual>
    <origin rpy="0 0 0" xyz="-0.075503 -0.052315 -0.079034"/>
    <geometry>
      <mesh filename="package://grid_bot_3_description/meshes/side_pane_1.stl" scale="0.001 0.001 0.001"/>
    </geometry>
    <material name="silver"/>
  </visual>
  <collision>
    <origin rpy="0 0 0" xyz="-0.075503 -0.052315 -0.079034"/>
    <geometry>
      <mesh filename="package://grid_bot_3_description/meshes/side_pane_1.stl" scale="0.001 0.001 0.001"/>
    </geometry>
  </collision>
</link>

<link name="connector_rod_1">
  <inertial>
    <origin rpy="0 0 0" xyz="3.890800441760933e-07 -0.06749956770909944 -2.161915329777775e-07"/>
    <mass value="0.007490931332944163"/>
    <inertia ixx="1.1e-05" ixy="-0.0" ixz="0.0" iyy="0.0" iyz="-0.0" izz="1.1e-05"/>
  </inertial>
  <visual>
    <origin rpy="0 0 0" xyz="-0.046539 -0.069315 0.028466"/>
    <geometry>
      <mesh filename="package://grid_bot_3_description/meshes/connector_rod_1.stl" scale="0.001 0.001 0.001"/>
    </geometry>
    <material name="silver"/>
  </visual>
  <collision>
    <origin rpy="0 0 0" xyz="-0.046539 -0.069315 0.028466"/>
    <geometry>
      <mesh filename="package://grid_bot_3_description/meshes/connector_rod_1.stl" scale="0.001 0.001 0.001"/>
    </geometry>
  </collision>
</link>

<link name="left_wheel_1">
  <inertial>
    <origin rpy="0 0 0" xyz="3.8680151746156577e-07 0.0042454206608824735 -2.2070271555110765e-07"/>
    <mass value="0.10624530732840641"/>
    <inertia ixx="2e-05" ixy="-0.0" ixz="-0.0" iyy="3.9e-05" iyz="-0.0" izz="2e-05"/>
  </inertial>
  <visual>
    <origin rpy="0 0 0" xyz="-0.046539 0.065685 0.028466"/>
    <geometry>
      <mesh filename="package://grid_bot_3_description/meshes/left_wheel_1.stl" scale="0.001 0.001 0.001"/>
    </geometry>
    <material name="silver"/>
  </visual>
  <collision>
    <origin rpy="0 0 0" xyz="-0.046539 0.065685 0.028466"/>
    <geometry>
      <mesh filename="package://grid_bot_3_description/meshes/left_wheel_1.stl" scale="0.001 0.001 0.001"/>
    </geometry>
  </collision>
</link>

<link name="right_wheel_1">
  <inertial>
    <origin rpy="0 0 0" xyz="3.8680151760034365e-07 -0.004244554213330684 -2.2070271556498544e-07"/>
    <mass value="0.10624530732840641"/>
    <inertia ixx="2e-05" ixy="-0.0" ixz="-0.0" iyy="3.9e-05" iyz="-0.0" izz="2e-05"/>
  </inertial>
  <visual>
    <origin rpy="0 0 0" xyz="-0.046539 -0.069315 0.028466"/>
    <geometry>
      <mesh filename="package://grid_bot_3_description/meshes/right_wheel_1.stl" scale="0.001 0.001 0.001"/>
    </geometry>
    <material name="silver"/>
  </visual>
  <collision>
    <origin rpy="0 0 0" xyz="-0.046539 -0.069315 0.028466"/>
    <geometry>
      <mesh filename="package://grid_bot_3_description/meshes/right_wheel_1.stl" scale="0.001 0.001 0.001"/>
    </geometry>
  </collision>
</link>

<link name="castor_wheel_1">
  <inertial>
    <origin rpy="0 0 0" xyz="-4.60694217933183e-06 1.876423122246793e-05 -0.007087258397097118"/>
    <mass value="0.036526757425163855"/>
    <inertia ixx="5e-06" ixy="-0.0" ixz="-0.0" iyy="4e-06" iyz="0.0" izz="5e-06"/>
  </inertial>
  <visual>
    <origin rpy="0 0 0" xyz="0.040997 -0.002315 0.031466"/>
    <geometry>
      <mesh filename="package://grid_bot_3_description/meshes/castor_wheel_1.stl" scale="0.001 0.001 0.001"/>
    </geometry>
    <material name="silver"/>
  </visual>
  <collision>
    <origin rpy="0 0 0" xyz="0.040997 -0.002315 0.031466"/>
    <geometry>
      <mesh filename="package://grid_bot_3_description/meshes/castor_wheel_1.stl" scale="0.001 0.001 0.001"/>
    </geometry>
  </collision>
</link>

<link name="left_wheel_tyre_1">
  <inertial>
    <origin rpy="0 0 0" xyz="3.890801221415052e-07 0.005000419728007896 -2.1619153321023044e-07"/>
    <mass value="0.003489570869816107"/>
    <inertia ixx="1e-06" ixy="0.0" ixz="-0.0" iyy="2e-06" iyz="0.0" izz="1e-06"/>
  </inertial>
  <visual>
    <origin rpy="0 0 0" xyz="-0.046539 0.06644 0.028466"/>
    <geometry>
      <mesh filename="package://grid_bot_3_description/meshes/left_wheel_tyre_1.stl" scale="0.001 0.001 0.001"/>
    </geometry>
    <material name="silver"/>
  </visual>
  <collision>
    <origin rpy="0 0 0" xyz="-0.046539 0.06644 0.028466"/>
    <geometry>
      <mesh filename="package://grid_bot_3_description/meshes/left_wheel_tyre_1.stl" scale="0.001 0.001 0.001"/>
    </geometry>
  </collision>
</link>

<link name="right_wheel_tyre_1">
  <inertial>
    <origin rpy="0 0 0" xyz="3.890801222733442e-07 -0.004999555146205259 -2.1619153322410822e-07"/>
    <mass value="0.003489570869816107"/>
    <inertia ixx="1e-06" ixy="-0.0" ixz="-0.0" iyy="2e-06" iyz="0.0" izz="1e-06"/>
  </inertial>
  <visual>
    <origin rpy="0 0 0" xyz="-0.046539 -0.07007 0.028466"/>
    <geometry>
      <mesh filename="package://grid_bot_3_description/meshes/right_wheel_tyre_1.stl" scale="0.001 0.001 0.001"/>
    </geometry>
    <material name="silver"/>
  </visual>
  <collision>
    <origin rpy="0 0 0" xyz="-0.046539 -0.07007 0.028466"/>
    <geometry>
      <mesh filename="package://grid_bot_3_description/meshes/right_wheel_tyre_1.stl" scale="0.001 0.001 0.001"/>
    </geometry>
  </collision>
</link>

<link name="identifier_1">
  <inertial>
    <origin rpy="0 0 0" xyz="-0.009280923887471766 0.00675453690073884 -0.00547128391777249"/>
    <mass value="0.00107596889014501"/>
    <inertia ixx="0.0" ixy="0.0" ixz="-0.0" iyy="1e-06" iyz="0.0" izz="1e-06"/>
  </inertial>
  <visual>
    <origin rpy="0 0 0" xyz="-0.043194 0.007558 -0.06724"/>
    <geometry>
      <mesh filename="package://grid_bot_3_description/meshes/identifier_1.stl" scale="0.001 0.001 0.001"/>
    </geometry>
    <material name="silver"/>
  </visual>
  <collision>
    <origin rpy="0 0 0" xyz="-0.043194 0.007558 -0.06724"/>
    <geometry>
      <mesh filename="package://grid_bot_3_description/meshes/identifier_1.stl" scale="0.001 0.001 0.001"/>
    </geometry>
  </collision>
</link>

<joint name="servo_fix" type="fixed">
  <origin rpy="0 0 0" xyz="-0.031681 0.002315 0.005433"/>
  <parent link="base_link"/>
  <child link="servo_motor_1"/>
</joint>

<joint name="servo_joint" type="revolute">
  <origin rpy="0 0 0" xyz="-0.003871 0.0 -0.002294"/>
  <parent link="servo_motor_1"/>
  <child link="servo_actuator_1"/>
  <axis xyz="0.860292 0.0 0.509802"/>
  <limit effort="100" lower="0.0" upper="3.141593" velocity="100"/>
</joint>

<joint name="left_pane_fix" type="fixed">
  <origin rpy="0 0 0" xyz="0.075503 -0.047685 0.079034"/>
  <parent link="base_link"/>
  <child link="side_pane_2"/>
</joint>

<joint name="right_pane_fix" type="fixed">
  <origin rpy="0 0 0" xyz="0.075503 0.052315 0.079034"/>
  <parent link="base_link"/>
  <child link="side_pane_1"/>
</joint>

<joint name="connector_fix" type="fixed">
  <origin rpy="0 0 0" xyz="0.046539 0.069315 -0.028466"/>
  <parent link="base_link"/>
  <child link="connector_rod_1"/>
</joint>

<joint name="left_wheel_joint" type="continuous">
  <origin rpy="0 0 0" xyz="0.0 -0.135 0.0"/>
  <parent link="connector_rod_1"/>
  <child link="left_wheel_1"/>
  <axis xyz="-0.0 -1.0 -0.0"/>
</joint>

<joint name="right_wheel_joint" type="continuous">
  <origin rpy="0 0 0" xyz="0.0 0.0 0.0"/>
  <parent link="connector_rod_1"/>
  <child link="right_wheel_1"/>
  <axis xyz="0.0 -1.0 0.0"/>
</joint>

<joint name="castor_joint" type="fixed">
  <origin rpy="0 0 0" xyz="-0.040997 0.002315 -0.031466"/>
  <parent link="base_link"/>
  <child link="castor_wheel_1"/>
</joint>

<joint name="left_tyre_fix" type="fixed">
  <origin rpy="0 0 0" xyz="0.0 -0.000755 0.0"/>
  <parent link="left_wheel_1"/>
  <child link="left_wheel_tyre_1"/>
</joint>

<joint name="right_tyre_fix" type="fixed">
  <origin rpy="0 0 0" xyz="0.0 0.000755 0.0"/>
  <parent link="right_wheel_1"/>
  <child link="right_wheel_tyre_1"/>
</joint>

<joint name="identifier_fix" type="fixed">
  <origin rpy="0 0 0" xyz="0.043194 -0.007558 0.06724"/>
  <parent link="base_link"/>
  <child link="identifier_1"/>
</joint>

</robot>
